application.app - ERROR:        Exception on / [GET]
Traceback (most recent call last):
  File "/usr/local/lib/python3.11/site-packages/flask/app.py", line 2528, in wsgi_app
    response = self.full_dispatch_request()
               ^^^^^^^^^^^^^^^^^^^^^^^^^^^^
  File "/usr/local/lib/python3.11/site-packages/flask/app.py", line 1825, in full_dispatch_request
    rv = self.handle_user_exception(e)
         ^^^^^^^^^^^^^^^^^^^^^^^^^^^^^
  File "/usr/local/lib/python3.11/site-packages/flask/app.py", line 1823, in full_dispatch_request
    rv = self.dispatch_request()
         ^^^^^^^^^^^^^^^^^^^^^^^
  File "/usr/local/lib/python3.11/site-packages/flask/app.py", line 1799, in dispatch_request
    return self.ensure_sync(self.view_functions[rule.endpoint])(**view_args)
           ^^^^^^^^^^^^^^^^^^^^^^^^^^^^^^^^^^^^^^^^^^^^^^^^^^^^^^^^^^^^^^^^^
  File "/usr/src/app/application/home/routes.py", line 25, in home
    picks = toolbox.find_breakout(strategies.get_adx_cross, db.df)
            ^^^^^^^^^^^^^^^^^^^^^^^^^^^^^^^^^^^^^^^^^^^^^^^^^^^^^^
  File "/usr/src/app/application/frameworks/toolbox.py", line 55, in find_breakout
    strike_float = float(data_copy.iloc[-1]['Close'])
                         ^^^^^^^^^
NameError: name 'data_copy' is not defined
application.app - ERROR:        Exception on / [GET]
Traceback (most recent call last):
  File "/usr/local/lib/python3.11/site-packages/flask/app.py", line 2528, in wsgi_app
    response = self.full_dispatch_request()
               ^^^^^^^^^^^^^^^^^^^^^^^^^^^^
  File "/usr/local/lib/python3.11/site-packages/flask/app.py", line 1825, in full_dispatch_request
    rv = self.handle_user_exception(e)
         ^^^^^^^^^^^^^^^^^^^^^^^^^^^^^
  File "/usr/local/lib/python3.11/site-packages/flask/app.py", line 1823, in full_dispatch_request
    rv = self.dispatch_request()
         ^^^^^^^^^^^^^^^^^^^^^^^
  File "/usr/local/lib/python3.11/site-packages/flask/app.py", line 1799, in dispatch_request
    return self.ensure_sync(self.view_functions[rule.endpoint])(**view_args)
           ^^^^^^^^^^^^^^^^^^^^^^^^^^^^^^^^^^^^^^^^^^^^^^^^^^^^^^^^^^^^^^^^^
  File "/usr/src/app/application/home/routes.py", line 25, in home
    picks = toolbox.find_breakout(strategies.get_adx_cross, db.df)
            ^^^^^^^^^^^^^^^^^^^^^^^^^^^^^^^^^^^^^^^^^^^^^^^^^^^^^^
TypeError: find_breakout() takes 1 positional argument but 2 were given
application.app - ERROR:        Exception on / [GET]
Traceback (most recent call last):
  File "/usr/local/lib/python3.11/site-packages/flask/app.py", line 2528, in wsgi_app
    response = self.full_dispatch_request()
               ^^^^^^^^^^^^^^^^^^^^^^^^^^^^
  File "/usr/local/lib/python3.11/site-packages/flask/app.py", line 1825, in full_dispatch_request
    rv = self.handle_user_exception(e)
         ^^^^^^^^^^^^^^^^^^^^^^^^^^^^^
  File "/usr/local/lib/python3.11/site-packages/flask/app.py", line 1823, in full_dispatch_request
    rv = self.dispatch_request()
         ^^^^^^^^^^^^^^^^^^^^^^^
  File "/usr/local/lib/python3.11/site-packages/flask/app.py", line 1799, in dispatch_request
    return self.ensure_sync(self.view_functions[rule.endpoint])(**view_args)
           ^^^^^^^^^^^^^^^^^^^^^^^^^^^^^^^^^^^^^^^^^^^^^^^^^^^^^^^^^^^^^^^^^
  File "/usr/src/app/application/home/routes.py", line 25, in home
    picks = toolbox.find_breakout(strategies.get_adx_cross)
            ^^^^^^^^^^^^^^^^^^^^^^^^^^^^^^^^^^^^^^^^^^^^^^^
  File "/usr/src/app/application/frameworks/toolbox.py", line 46, in find_breakout
    symbols = data.columns.get_level_values(0).unique().sort_values(ascending=True)
              ^^^^
NameError: name 'data' is not defined
application.app - ERROR:        Exception on / [GET]
Traceback (most recent call last):
  File "/usr/local/lib/python3.11/site-packages/pandas/core/indexes/base.py", line 3652, in get_loc
    return self._engine.get_loc(casted_key)
           ^^^^^^^^^^^^^^^^^^^^^^^^^^^^^^^^
  File "pandas/_libs/index.pyx", line 147, in pandas._libs.index.IndexEngine.get_loc
  File "pandas/_libs/index.pyx", line 176, in pandas._libs.index.IndexEngine.get_loc
  File "pandas/_libs/hashtable_class_helper.pxi", line 7080, in pandas._libs.hashtable.PyObjectHashTable.get_item
  File "pandas/_libs/hashtable_class_helper.pxi", line 7088, in pandas._libs.hashtable.PyObjectHashTable.get_item
KeyError: 'Close'

The above exception was the direct cause of the following exception:

Traceback (most recent call last):
  File "/usr/local/lib/python3.11/site-packages/flask/app.py", line 2528, in wsgi_app
    response = self.full_dispatch_request()
               ^^^^^^^^^^^^^^^^^^^^^^^^^^^^
  File "/usr/local/lib/python3.11/site-packages/flask/app.py", line 1825, in full_dispatch_request
    rv = self.handle_user_exception(e)
         ^^^^^^^^^^^^^^^^^^^^^^^^^^^^^
  File "/usr/local/lib/python3.11/site-packages/flask/app.py", line 1823, in full_dispatch_request
    rv = self.dispatch_request()
         ^^^^^^^^^^^^^^^^^^^^^^^
  File "/usr/local/lib/python3.11/site-packages/flask/app.py", line 1799, in dispatch_request
    return self.ensure_sync(self.view_functions[rule.endpoint])(**view_args)
           ^^^^^^^^^^^^^^^^^^^^^^^^^^^^^^^^^^^^^^^^^^^^^^^^^^^^^^^^^^^^^^^^^
  File "/usr/src/app/application/home/routes.py", line 25, in home
    picks = toolbox.find_breakout(strategies.get_adx_cross)
            ^^^^^^^^^^^^^^^^^^^^^^^^^^^^^^^^^^^^^^^^^^^^^^^
  File "/usr/src/app/application/frameworks/toolbox.py", line 55, in find_breakout
    strike_float = float(strategy_df.iloc[-1]['Close'])
                         ~~~~~~~~~~~~~~~~~~~~^^^^^^^^^
  File "/usr/local/lib/python3.11/site-packages/pandas/core/series.py", line 1012, in __getitem__
    return self._get_value(key)
           ^^^^^^^^^^^^^^^^^^^^
  File "/usr/local/lib/python3.11/site-packages/pandas/core/series.py", line 1121, in _get_value
    loc = self.index.get_loc(label)
          ^^^^^^^^^^^^^^^^^^^^^^^^^
  File "/usr/local/lib/python3.11/site-packages/pandas/core/indexes/multi.py", line 2811, in get_loc
    loc = self._get_level_indexer(key, level=0)
          ^^^^^^^^^^^^^^^^^^^^^^^^^^^^^^^^^^^^^
  File "/usr/local/lib/python3.11/site-packages/pandas/core/indexes/multi.py", line 3159, in _get_level_indexer
    idx = self._get_loc_single_level_index(level_index, key)
          ^^^^^^^^^^^^^^^^^^^^^^^^^^^^^^^^^^^^^^^^^^^^^^^^^^
  File "/usr/local/lib/python3.11/site-packages/pandas/core/indexes/multi.py", line 2751, in _get_loc_single_level_index
    return level_index.get_loc(key)
           ^^^^^^^^^^^^^^^^^^^^^^^^
  File "/usr/local/lib/python3.11/site-packages/pandas/core/indexes/base.py", line 3654, in get_loc
    raise KeyError(key) from err
KeyError: 'Close'
application.app - ERROR:        Exception on / [GET]
Traceback (most recent call last):
  File "/usr/local/lib/python3.11/site-packages/pandas/core/indexes/base.py", line 3652, in get_loc
    return self._engine.get_loc(casted_key)
           ^^^^^^^^^^^^^^^^^^^^^^^^^^^^^^^^
  File "pandas/_libs/index.pyx", line 147, in pandas._libs.index.IndexEngine.get_loc
  File "pandas/_libs/index.pyx", line 176, in pandas._libs.index.IndexEngine.get_loc
  File "pandas/_libs/hashtable_class_helper.pxi", line 7080, in pandas._libs.hashtable.PyObjectHashTable.get_item
  File "pandas/_libs/hashtable_class_helper.pxi", line 7088, in pandas._libs.hashtable.PyObjectHashTable.get_item
KeyError: 'xo'

The above exception was the direct cause of the following exception:

Traceback (most recent call last):
  File "/usr/local/lib/python3.11/site-packages/flask/app.py", line 2528, in wsgi_app
    response = self.full_dispatch_request()
               ^^^^^^^^^^^^^^^^^^^^^^^^^^^^
  File "/usr/local/lib/python3.11/site-packages/flask/app.py", line 1825, in full_dispatch_request
    rv = self.handle_user_exception(e)
         ^^^^^^^^^^^^^^^^^^^^^^^^^^^^^
  File "/usr/local/lib/python3.11/site-packages/flask/app.py", line 1823, in full_dispatch_request
    rv = self.dispatch_request()
         ^^^^^^^^^^^^^^^^^^^^^^^
  File "/usr/local/lib/python3.11/site-packages/flask/app.py", line 1799, in dispatch_request
    return self.ensure_sync(self.view_functions[rule.endpoint])(**view_args)
           ^^^^^^^^^^^^^^^^^^^^^^^^^^^^^^^^^^^^^^^^^^^^^^^^^^^^^^^^^^^^^^^^^
  File "/usr/src/app/application/home/routes.py", line 25, in home
    picks = toolbox.find_breakout(strategies.get_adx_cross, db.df)
            ^^^^^^^^^^^^^^^^^^^^^^^^^^^^^^^^^^^^^^^^^^^^^^^^^^^^^^
  File "/usr/src/app/application/frameworks/toolbox.py", line 63, in find_breakout
    if len(df[df['xo'] == True]) > 1:
              ~~^^^^^^
  File "/usr/local/lib/python3.11/site-packages/pandas/core/frame.py", line 3759, in __getitem__
    return self._getitem_multilevel(key)
           ^^^^^^^^^^^^^^^^^^^^^^^^^^^^^
  File "/usr/local/lib/python3.11/site-packages/pandas/core/frame.py", line 3814, in _getitem_multilevel
    loc = self.columns.get_loc(key)
          ^^^^^^^^^^^^^^^^^^^^^^^^^
  File "/usr/local/lib/python3.11/site-packages/pandas/core/indexes/multi.py", line 2811, in get_loc
    loc = self._get_level_indexer(key, level=0)
          ^^^^^^^^^^^^^^^^^^^^^^^^^^^^^^^^^^^^^
  File "/usr/local/lib/python3.11/site-packages/pandas/core/indexes/multi.py", line 3159, in _get_level_indexer
    idx = self._get_loc_single_level_index(level_index, key)
          ^^^^^^^^^^^^^^^^^^^^^^^^^^^^^^^^^^^^^^^^^^^^^^^^^^
  File "/usr/local/lib/python3.11/site-packages/pandas/core/indexes/multi.py", line 2751, in _get_loc_single_level_index
    return level_index.get_loc(key)
           ^^^^^^^^^^^^^^^^^^^^^^^^
  File "/usr/local/lib/python3.11/site-packages/pandas/core/indexes/base.py", line 3654, in get_loc
    raise KeyError(key) from err
KeyError: 'xo'
application.app - ERROR:        Exception on / [GET]
Traceback (most recent call last):
  File "/usr/local/lib/python3.11/site-packages/pandas/core/indexes/base.py", line 3652, in get_loc
    return self._engine.get_loc(casted_key)
           ^^^^^^^^^^^^^^^^^^^^^^^^^^^^^^^^
  File "pandas/_libs/index.pyx", line 147, in pandas._libs.index.IndexEngine.get_loc
  File "pandas/_libs/index.pyx", line 176, in pandas._libs.index.IndexEngine.get_loc
  File "pandas/_libs/hashtable_class_helper.pxi", line 7080, in pandas._libs.hashtable.PyObjectHashTable.get_item
  File "pandas/_libs/hashtable_class_helper.pxi", line 7088, in pandas._libs.hashtable.PyObjectHashTable.get_item
KeyError: 'xo'

The above exception was the direct cause of the following exception:

Traceback (most recent call last):
  File "/usr/local/lib/python3.11/site-packages/flask/app.py", line 2528, in wsgi_app
    response = self.full_dispatch_request()
               ^^^^^^^^^^^^^^^^^^^^^^^^^^^^
  File "/usr/local/lib/python3.11/site-packages/flask/app.py", line 1825, in full_dispatch_request
    rv = self.handle_user_exception(e)
         ^^^^^^^^^^^^^^^^^^^^^^^^^^^^^
  File "/usr/local/lib/python3.11/site-packages/flask/app.py", line 1823, in full_dispatch_request
    rv = self.dispatch_request()
         ^^^^^^^^^^^^^^^^^^^^^^^
  File "/usr/local/lib/python3.11/site-packages/flask/app.py", line 1799, in dispatch_request
    return self.ensure_sync(self.view_functions[rule.endpoint])(**view_args)
           ^^^^^^^^^^^^^^^^^^^^^^^^^^^^^^^^^^^^^^^^^^^^^^^^^^^^^^^^^^^^^^^^^
  File "/usr/src/app/application/home/routes.py", line 25, in home
    picks = toolbox.find_breakout(strategies.get_adx_cross, db.df)
            ^^^^^^^^^^^^^^^^^^^^^^^^^^^^^^^^^^^^^^^^^^^^^^^^^^^^^^
  File "/usr/src/app/application/frameworks/toolbox.py", line 63, in find_breakout
    if len(df[df['xo'] == True]) > 1:
              ~~^^^^^^
  File "/usr/local/lib/python3.11/site-packages/pandas/core/frame.py", line 3759, in __getitem__
    return self._getitem_multilevel(key)
           ^^^^^^^^^^^^^^^^^^^^^^^^^^^^^
  File "/usr/local/lib/python3.11/site-packages/pandas/core/frame.py", line 3814, in _getitem_multilevel
    loc = self.columns.get_loc(key)
          ^^^^^^^^^^^^^^^^^^^^^^^^^
  File "/usr/local/lib/python3.11/site-packages/pandas/core/indexes/multi.py", line 2811, in get_loc
    loc = self._get_level_indexer(key, level=0)
          ^^^^^^^^^^^^^^^^^^^^^^^^^^^^^^^^^^^^^
  File "/usr/local/lib/python3.11/site-packages/pandas/core/indexes/multi.py", line 3159, in _get_level_indexer
    idx = self._get_loc_single_level_index(level_index, key)
          ^^^^^^^^^^^^^^^^^^^^^^^^^^^^^^^^^^^^^^^^^^^^^^^^^^
  File "/usr/local/lib/python3.11/site-packages/pandas/core/indexes/multi.py", line 2751, in _get_loc_single_level_index
    return level_index.get_loc(key)
           ^^^^^^^^^^^^^^^^^^^^^^^^
  File "/usr/local/lib/python3.11/site-packages/pandas/core/indexes/base.py", line 3654, in get_loc
    raise KeyError(key) from err
KeyError: 'xo'
application.app - ERROR:        Exception on / [GET]
Traceback (most recent call last):
  File "/usr/local/lib/python3.11/site-packages/pandas/core/indexes/base.py", line 3652, in get_loc
    return self._engine.get_loc(casted_key)
           ^^^^^^^^^^^^^^^^^^^^^^^^^^^^^^^^
  File "pandas/_libs/index.pyx", line 147, in pandas._libs.index.IndexEngine.get_loc
  File "pandas/_libs/index.pyx", line 176, in pandas._libs.index.IndexEngine.get_loc
  File "pandas/_libs/hashtable_class_helper.pxi", line 7080, in pandas._libs.hashtable.PyObjectHashTable.get_item
  File "pandas/_libs/hashtable_class_helper.pxi", line 7088, in pandas._libs.hashtable.PyObjectHashTable.get_item
KeyError: 'xo'

The above exception was the direct cause of the following exception:

Traceback (most recent call last):
  File "/usr/local/lib/python3.11/site-packages/flask/app.py", line 2528, in wsgi_app
    response = self.full_dispatch_request()
               ^^^^^^^^^^^^^^^^^^^^^^^^^^^^
  File "/usr/local/lib/python3.11/site-packages/flask/app.py", line 1825, in full_dispatch_request
    rv = self.handle_user_exception(e)
         ^^^^^^^^^^^^^^^^^^^^^^^^^^^^^
  File "/usr/local/lib/python3.11/site-packages/flask/app.py", line 1823, in full_dispatch_request
    rv = self.dispatch_request()
         ^^^^^^^^^^^^^^^^^^^^^^^
  File "/usr/local/lib/python3.11/site-packages/flask/app.py", line 1799, in dispatch_request
    return self.ensure_sync(self.view_functions[rule.endpoint])(**view_args)
           ^^^^^^^^^^^^^^^^^^^^^^^^^^^^^^^^^^^^^^^^^^^^^^^^^^^^^^^^^^^^^^^^^
  File "/usr/src/app/application/home/routes.py", line 25, in home
    picks = toolbox.find_breakout(strategies.get_adx_cross, db.df)
            ^^^^^^^^^^^^^^^^^^^^^^^^^^^^^^^^^^^^^^^^^^^^^^^^^^^^^^
  File "/usr/src/app/application/frameworks/toolbox.py", line 63, in find_breakout
    if len(df[df['xo'] == True]) > 1:
              ~~^^^^^^
  File "/usr/local/lib/python3.11/site-packages/pandas/core/frame.py", line 3759, in __getitem__
    return self._getitem_multilevel(key)
           ^^^^^^^^^^^^^^^^^^^^^^^^^^^^^
  File "/usr/local/lib/python3.11/site-packages/pandas/core/frame.py", line 3814, in _getitem_multilevel
    loc = self.columns.get_loc(key)
          ^^^^^^^^^^^^^^^^^^^^^^^^^
  File "/usr/local/lib/python3.11/site-packages/pandas/core/indexes/multi.py", line 2811, in get_loc
    loc = self._get_level_indexer(key, level=0)
          ^^^^^^^^^^^^^^^^^^^^^^^^^^^^^^^^^^^^^
  File "/usr/local/lib/python3.11/site-packages/pandas/core/indexes/multi.py", line 3159, in _get_level_indexer
    idx = self._get_loc_single_level_index(level_index, key)
          ^^^^^^^^^^^^^^^^^^^^^^^^^^^^^^^^^^^^^^^^^^^^^^^^^^
  File "/usr/local/lib/python3.11/site-packages/pandas/core/indexes/multi.py", line 2751, in _get_loc_single_level_index
    return level_index.get_loc(key)
           ^^^^^^^^^^^^^^^^^^^^^^^^
  File "/usr/local/lib/python3.11/site-packages/pandas/core/indexes/base.py", line 3654, in get_loc
    raise KeyError(key) from err
KeyError: 'xo'
application.app - ERROR:        Exception on / [GET]
Traceback (most recent call last):
  File "/usr/local/lib/python3.11/site-packages/pandas/core/indexes/base.py", line 3652, in get_loc
    return self._engine.get_loc(casted_key)
           ^^^^^^^^^^^^^^^^^^^^^^^^^^^^^^^^
  File "pandas/_libs/index.pyx", line 147, in pandas._libs.index.IndexEngine.get_loc
  File "pandas/_libs/index.pyx", line 176, in pandas._libs.index.IndexEngine.get_loc
  File "pandas/_libs/hashtable_class_helper.pxi", line 7080, in pandas._libs.hashtable.PyObjectHashTable.get_item
  File "pandas/_libs/hashtable_class_helper.pxi", line 7088, in pandas._libs.hashtable.PyObjectHashTable.get_item
KeyError: 'DMN_14'

The above exception was the direct cause of the following exception:

Traceback (most recent call last):
  File "/usr/local/lib/python3.11/site-packages/flask/app.py", line 2528, in wsgi_app
    response = self.full_dispatch_request()
               ^^^^^^^^^^^^^^^^^^^^^^^^^^^^
  File "/usr/local/lib/python3.11/site-packages/flask/app.py", line 1825, in full_dispatch_request
    rv = self.handle_user_exception(e)
         ^^^^^^^^^^^^^^^^^^^^^^^^^^^^^
  File "/usr/local/lib/python3.11/site-packages/flask/app.py", line 1823, in full_dispatch_request
    rv = self.dispatch_request()
         ^^^^^^^^^^^^^^^^^^^^^^^
  File "/usr/local/lib/python3.11/site-packages/flask/app.py", line 1799, in dispatch_request
    return self.ensure_sync(self.view_functions[rule.endpoint])(**view_args)
           ^^^^^^^^^^^^^^^^^^^^^^^^^^^^^^^^^^^^^^^^^^^^^^^^^^^^^^^^^^^^^^^^^
  File "/usr/src/app/application/home/routes.py", line 25, in home
    picks = toolbox.find_breakout(strategies.get_adx_cross, db.df)
            ^^^^^^^^^^^^^^^^^^^^^^^^^^^^^^^^^^^^^^^^^^^^^^^^^^^^^^
  File "/usr/src/app/application/frameworks/toolbox.py", line 87, in find_breakout
    dmi_downtrend = (adx.tail(1)['DMN_14'] > adx.tail(1)['DMP_14']).bool()
                     ~~~~~~~~~~~^^^^^^^^^^
  File "/usr/local/lib/python3.11/site-packages/pandas/core/frame.py", line 3759, in __getitem__
    return self._getitem_multilevel(key)
           ^^^^^^^^^^^^^^^^^^^^^^^^^^^^^
  File "/usr/local/lib/python3.11/site-packages/pandas/core/frame.py", line 3814, in _getitem_multilevel
    loc = self.columns.get_loc(key)
          ^^^^^^^^^^^^^^^^^^^^^^^^^
  File "/usr/local/lib/python3.11/site-packages/pandas/core/indexes/multi.py", line 2811, in get_loc
    loc = self._get_level_indexer(key, level=0)
          ^^^^^^^^^^^^^^^^^^^^^^^^^^^^^^^^^^^^^
  File "/usr/local/lib/python3.11/site-packages/pandas/core/indexes/multi.py", line 3159, in _get_level_indexer
    idx = self._get_loc_single_level_index(level_index, key)
          ^^^^^^^^^^^^^^^^^^^^^^^^^^^^^^^^^^^^^^^^^^^^^^^^^^
  File "/usr/local/lib/python3.11/site-packages/pandas/core/indexes/multi.py", line 2751, in _get_loc_single_level_index
    return level_index.get_loc(key)
           ^^^^^^^^^^^^^^^^^^^^^^^^
  File "/usr/local/lib/python3.11/site-packages/pandas/core/indexes/base.py", line 3654, in get_loc
    raise KeyError(key) from err
KeyError: 'DMN_14'
application.app - ERROR:        Exception on / [GET]
Traceback (most recent call last):
  File "/usr/local/lib/python3.11/site-packages/flask/app.py", line 2528, in wsgi_app
    response = self.full_dispatch_request()
               ^^^^^^^^^^^^^^^^^^^^^^^^^^^^
  File "/usr/local/lib/python3.11/site-packages/flask/app.py", line 1825, in full_dispatch_request
    rv = self.handle_user_exception(e)
         ^^^^^^^^^^^^^^^^^^^^^^^^^^^^^
  File "/usr/local/lib/python3.11/site-packages/flask/app.py", line 1823, in full_dispatch_request
    rv = self.dispatch_request()
         ^^^^^^^^^^^^^^^^^^^^^^^
  File "/usr/local/lib/python3.11/site-packages/flask/app.py", line 1799, in dispatch_request
    return self.ensure_sync(self.view_functions[rule.endpoint])(**view_args)
           ^^^^^^^^^^^^^^^^^^^^^^^^^^^^^^^^^^^^^^^^^^^^^^^^^^^^^^^^^^^^^^^^^
  File "/usr/src/app/application/home/routes.py", line 26, in home
    return render_template(
           ^^^^^^^^^^^^^^^^
  File "/usr/local/lib/python3.11/site-packages/flask/templating.py", line 147, in render_template
    return _render(app, template, context)
           ^^^^^^^^^^^^^^^^^^^^^^^^^^^^^^^
  File "/usr/local/lib/python3.11/site-packages/flask/templating.py", line 130, in _render
    rv = template.render(context)
         ^^^^^^^^^^^^^^^^^^^^^^^^
  File "/usr/local/lib/python3.11/site-packages/jinja2/environment.py", line 1301, in render
    self.environment.handle_exception()
  File "/usr/local/lib/python3.11/site-packages/jinja2/environment.py", line 936, in handle_exception
    raise rewrite_traceback_stack(source=source)
  File "/usr/src/app/application/home/templates/page.html", line 1, in top-level template code
    {% extends 'template.j2' %}
    ^^^^^^^^^^^^^^^^^^^^^^^^^
  File "/usr/src/app/application/templates/template.j2", line 31, in top-level template code
    {% block body %}{% endblock %}
    ^^^^^^^^^^^^^^^^^^^^^^^^^
  File "/usr/src/app/application/home/templates/page.html", line 23, in block 'body'
    {% for pick in picks %}
TypeError: 'NoneType' object is not iterable
application.app - ERROR:        Exception on /strategy/golden_cross [GET]
Traceback (most recent call last):
  File "/usr/local/lib/python3.11/site-packages/flask/app.py", line 2528, in wsgi_app
    response = self.full_dispatch_request()
               ^^^^^^^^^^^^^^^^^^^^^^^^^^^^
  File "/usr/local/lib/python3.11/site-packages/flask/app.py", line 1825, in full_dispatch_request
    rv = self.handle_user_exception(e)
         ^^^^^^^^^^^^^^^^^^^^^^^^^^^^^
  File "/usr/local/lib/python3.11/site-packages/flask/app.py", line 1823, in full_dispatch_request
    rv = self.dispatch_request()
         ^^^^^^^^^^^^^^^^^^^^^^^
  File "/usr/local/lib/python3.11/site-packages/flask/app.py", line 1799, in dispatch_request
    return self.ensure_sync(self.view_functions[rule.endpoint])(**view_args)
           ^^^^^^^^^^^^^^^^^^^^^^^^^^^^^^^^^^^^^^^^^^^^^^^^^^^^^^^^^^^^^^^^^
  File "/usr/src/app/application/golden_cross/routes.py", line 25, in golden_cross
    picks = toolbox.find_breakout(strategies.get_golden_cross, db.df)
            ^^^^^^^^^^^^^^^^^^^^^^^^^^^^^^^^^^^^^^^^^^^^^^^^^^^^^^^^^
  File "/usr/src/app/application/frameworks/toolbox.py", line 50, in find_breakout
    strategy_df = pd.read_hdf(os.path.join('data', strategy_name + '.h5'))
                  ^^^^^^^^^^^^^^^^^^^^^^^^^^^^^^^^^^^^^^^^^^^^^^^^^^^^^^^^
  File "/usr/local/lib/python3.11/site-packages/pandas/io/pytables.py", line 446, in read_hdf
    return store.select(
           ^^^^^^^^^^^^^
  File "/usr/local/lib/python3.11/site-packages/pandas/io/pytables.py", line 866, in select
    return it.get_result()
           ^^^^^^^^^^^^^^^
  File "/usr/local/lib/python3.11/site-packages/pandas/io/pytables.py", line 1937, in get_result
    results = self.func(self.start, self.stop, where)
              ^^^^^^^^^^^^^^^^^^^^^^^^^^^^^^^^^^^^^^^
  File "/usr/local/lib/python3.11/site-packages/pandas/io/pytables.py", line 850, in func
    return s.read(start=_start, stop=_stop, where=_where, columns=columns)
           ^^^^^^^^^^^^^^^^^^^^^^^^^^^^^^^^^^^^^^^^^^^^^^^^^^^^^^^^^^^^^^^
  File "/usr/local/lib/python3.11/site-packages/pandas/io/pytables.py", line 3184, in read
    ax = self.read_index(f"axis{i}", start=_start, stop=_stop)
         ^^^^^^^^^^^^^^^^^^^^^^^^^^^^^^^^^^^^^^^^^^^^^^^^^^^^^
  File "/usr/local/lib/python3.11/site-packages/pandas/io/pytables.py", line 2888, in read_index
    return self.read_multi_index(key, start=start, stop=stop)
           ^^^^^^^^^^^^^^^^^^^^^^^^^^^^^^^^^^^^^^^^^^^^^^^^^^
  File "/usr/local/lib/python3.11/site-packages/pandas/io/pytables.py", line 2954, in read_multi_index
    node = getattr(self.group, level_key)
           ^^^^^^^^^^^^^^^^^^^^^^^^^^^^^^
  File "/usr/local/lib/python3.11/site-packages/tables/group.py", line 798, in __getattr__
    return self._f_get_child(name)
           ^^^^^^^^^^^^^^^^^^^^^^^
  File "/usr/local/lib/python3.11/site-packages/tables/group.py", line 685, in _f_get_child
    return self._v_file._get_node(childpath)
           ^^^^^^^^^^^^^^^^^^^^^^^^^^^^^^^^^
  File "/usr/local/lib/python3.11/site-packages/tables/file.py", line 1556, in _get_node
    node = self._node_manager.get_node(nodepath)
           ^^^^^^^^^^^^^^^^^^^^^^^^^^^^^^^^^^^^^
  File "/usr/local/lib/python3.11/site-packages/tables/file.py", line 417, in get_node
    node = self.node_factory(key)
           ^^^^^^^^^^^^^^^^^^^^^^
  File "/usr/local/lib/python3.11/site-packages/tables/group.py", line 1153, in _g_load_child
    ChildClass = self._g_get_child_leaf_class(childname, warn=True)
                 ^^^^^^^^^^^^^^^^^^^^^^^^^^^^^^^^^^^^^^^^^^^^^^^^^^
  File "/usr/local/lib/python3.11/site-packages/tables/group.py", line 296, in _g_get_child_leaf_class
    childCID = self._g_get_lchild_attr(childname, 'CLASS')
               ^^^^^^^^^^^^^^^^^^^^^^^^^^^^^^^^^^^^^^^^^^^
  File "tables/hdf5extension.pyx", line 1064, in tables.hdf5extension.Group._g_get_lchild_attr
  File "tables/hdf5extension.pyx", line 235, in tables.hdf5extension.get_attribute_string_or_none
SystemError: Negative size passed to PyBytes_FromStringAndSize
application.app - ERROR:        Exception on /strategy/adx_cross [GET]
Traceback (most recent call last):
  File "/usr/local/lib/python3.11/site-packages/flask/app.py", line 2528, in wsgi_app
    response = self.full_dispatch_request()
               ^^^^^^^^^^^^^^^^^^^^^^^^^^^^
  File "/usr/local/lib/python3.11/site-packages/flask/app.py", line 1825, in full_dispatch_request
    rv = self.handle_user_exception(e)
         ^^^^^^^^^^^^^^^^^^^^^^^^^^^^^
  File "/usr/local/lib/python3.11/site-packages/flask/app.py", line 1823, in full_dispatch_request
    rv = self.dispatch_request()
         ^^^^^^^^^^^^^^^^^^^^^^^
  File "/usr/local/lib/python3.11/site-packages/flask/app.py", line 1799, in dispatch_request
    return self.ensure_sync(self.view_functions[rule.endpoint])(**view_args)
           ^^^^^^^^^^^^^^^^^^^^^^^^^^^^^^^^^^^^^^^^^^^^^^^^^^^^^^^^^^^^^^^^^
  File "/usr/src/app/application/adx_cross/routes.py", line 25, in adx_cross
    picks = toolbox.find_breakout(strategies.get_adx_cross, db.df)
            ^^^^^^^^^^^^^^^^^^^^^^^^^^^^^^^^^^^^^^^^^^^^^^^^^^^^^^
  File "/usr/src/app/application/frameworks/toolbox.py", line 52, in find_breakout
    stochrsi = pd.read_hdf(os.path.join('data', 'stochrsi.h5'))
               ^^^^^^^^^^^^^^^^^^^^^^^^^^^^^^^^^^^^^^^^^^^^^^^^
  File "/usr/local/lib/python3.11/site-packages/pandas/io/pytables.py", line 446, in read_hdf
    return store.select(
           ^^^^^^^^^^^^^
  File "/usr/local/lib/python3.11/site-packages/pandas/io/pytables.py", line 866, in select
    return it.get_result()
           ^^^^^^^^^^^^^^^
  File "/usr/local/lib/python3.11/site-packages/pandas/io/pytables.py", line 1937, in get_result
    results = self.func(self.start, self.stop, where)
              ^^^^^^^^^^^^^^^^^^^^^^^^^^^^^^^^^^^^^^^
  File "/usr/local/lib/python3.11/site-packages/pandas/io/pytables.py", line 850, in func
    return s.read(start=_start, stop=_stop, where=_where, columns=columns)
           ^^^^^^^^^^^^^^^^^^^^^^^^^^^^^^^^^^^^^^^^^^^^^^^^^^^^^^^^^^^^^^^
  File "/usr/local/lib/python3.11/site-packages/pandas/io/pytables.py", line 3184, in read
    ax = self.read_index(f"axis{i}", start=_start, stop=_stop)
         ^^^^^^^^^^^^^^^^^^^^^^^^^^^^^^^^^^^^^^^^^^^^^^^^^^^^^
  File "/usr/local/lib/python3.11/site-packages/pandas/io/pytables.py", line 2890, in read_index
    node = getattr(self.group, key)
           ^^^^^^^^^^^^^^^^^^^^^^^^
  File "/usr/local/lib/python3.11/site-packages/tables/group.py", line 798, in __getattr__
    return self._f_get_child(name)
           ^^^^^^^^^^^^^^^^^^^^^^^
  File "/usr/local/lib/python3.11/site-packages/tables/group.py", line 682, in _f_get_child
    self._g_check_has_child(childname)
  File "/usr/local/lib/python3.11/site-packages/tables/group.py", line 375, in _g_check_has_child
    raise NoSuchNodeError(
tables.exceptions.NoSuchNodeError: group ``/data`` does not have a child named ``axis1``
